Workbook

Sheet Dashboard
A1: HOUSE FLIP REHAB DASHBOARD
A2: WORKED EXAMPLE: $112,000 purchase | $285,000 ARV | 1,500 sf. Replace example inputs before evaluating a real property.
A3: Use Cost Dashboard to compare ballpark vs detailed costs. Positive variance means the detailed takeoff is above the original benchmark.
A4: ="Selected Rehab"&CHAR(10)&TEXT(SUM('Scope Builder'!U2:U251),"$#,##0") -> Selected Rehab $96,690 | D4: ="Critical / P0 Cost"&CHAR(10)&TEXT(SUMIFS('Scope Builder'!U2:U251,'Scope Builder'!A2:A251,"Yes",'Scope Builder'!I2:I251,"Critical")+SUMIFS('Scope Builder'!U2:U251,'Scope Builder'!A2:A251,"Yes",'Scope Builder'!K2:K251,"P0 - Immediate/Safety"),"$#,##0") -> Critical / P0 Cost $23,815 | G4: ="Projected Profit"&CHAR(10)&TEXT('Flip Analysis'!C12,"$#,##0") -> Projected Profit $38,270 | J4: ="Detailed MAO"&CHAR(10)&TEXT('Flip Analysis'!C16,"$#,##0") -> Detailed MAO $115,206
A8: RISK & SCOPE SUMMARY | H8: BUDGET BY PRIORITY
A9: Included Scope Items | D9: =COUNTIF('Scope Builder'!A2:A251,"Yes") -> 14 | H9: Priority | I9: Budget
A10: Critical Items | D10: =COUNTIFS('Scope Builder'!A2:A251,"Yes",'Scope Builder'!I2:I251,"Critical") -> 4 | H10: P0 - Immediate/Safety | I10: =SUMIFS('Scope Builder'!$U$2:$U$251,'Scope Builder'!$A$2:$A$251,"Yes",'Scope Builder'!$K$2:$K$251,H10) -> 0
A11: P0 Immediate/Safety | D11: =COUNTIFS('Scope Builder'!A2:A251,"Yes",'Scope Builder'!K2:K251,"P0 - Immediate/Safety") -> 0 | H11: P1 - Before Offer | I11: =SUMIFS('Scope Builder'!$U$2:$U$251,'Scope Builder'!$A$2:$A$251,"Yes",'Scope Builder'!$K$2:$K$251,H11) -> 24695
A12: P1 Before Offer | D12: =COUNTIFS('Scope Builder'!A2:A251,"Yes",'Scope Builder'!K2:K251,"P1 - Before Offer") -> 6 | H12: P2 - Before Sale | I12: =SUMIFS('Scope Builder'!$U$2:$U$251,'Scope Builder'!$A$2:$A$251,"Yes",'Scope Builder'!$K$2:$K$251,H12) -> 14630
A13: Permit-Required Items | D13: =COUNTIFS('Scope Builder'!A2:A251,"Yes",'Scope Builder'!W2:W251,"Yes") -> 4 | H13: P3 - Value Add | I13: =SUMIFS('Scope Builder'!$U$2:$U$251,'Scope Builder'!$A$2:$A$251,"Yes",'Scope Builder'!$K$2:$K$251,H13) -> 57365
A14: Contractor Quotes Entered | D14: =COUNTIFS('Scope Builder'!A2:A251,"Yes",'Scope Builder'!Q2:Q251,">0") -> 3 | H14: P4 - Optional | I14: =SUMIFS('Scope Builder'!$U$2:$U$251,'Scope Builder'!$A$2:$A$251,"Yes",'Scope Builder'!$K$2:$K$251,H14) -> 0
A16: BUDGET BY CATEGORY | H16: DEAL CHECKS
A17: Category | B17: Budget | H17: ARV | K17: ='Flip Analysis'!C5 -> 285000
A18: Appliances & Curb Appeal | B18: =SUMIFS('Scope Builder'!$U$2:$U$251,'Scope Builder'!$A$2:$A$251,"Yes",'Scope Builder'!$C$2:$C$251,A18) -> 495 | H18: Total Rehab | K18: ='Flip Analysis'!C6 -> 96690
A19: Basement & Environmental | B19: =SUMIFS('Scope Builder'!$U$2:$U$251,'Scope Builder'!$A$2:$A$251,"Yes",'Scope Builder'!$C$2:$C$251,A19) -> 0 | H19: Total Project Cost | K19: ='Flip Analysis'!C11 -> 246730
A20: Bathrooms | B20: =SUMIFS('Scope Builder'!$U$2:$U$251,'Scope Builder'!$A$2:$A$251,"Yes",'Scope Builder'!$C$2:$C$251,A20) -> 13970 | H20: Projected Profit | K20: ='Flip Analysis'!C12 -> 38270
A21: Electrical | B21: =SUMIFS('Scope Builder'!$U$2:$U$251,'Scope Builder'!$A$2:$A$251,"Yes",'Scope Builder'!$C$2:$C$251,A21) -> 3960 | H21: Profit Margin | K21: ='Flip Analysis'!C13 -> 0.1342807
A22: Exterior & Site | B22: =SUMIFS('Scope Builder'!$U$2:$U$251,'Scope Builder'!$A$2:$A$251,"Yes",'Scope Builder'!$C$2:$C$251,A22) -> 2530 | H22: Cash-on-Cost ROI | K22: ='Flip Analysis'!C14 -> 0.15510882
A23: Flooring | B23: =SUMIFS('Scope Builder'!$U$2:$U$251,'Scope Builder'!$A$2:$A$251,"Yes",'Scope Builder'!$C$2:$C$251,A23) -> 8360 | H23: 70% Rule MAO | K23: ='Flip Analysis'!C15 -> 102810
A24: HVAC | B24: =SUMIFS('Scope Builder'!$U$2:$U$251,'Scope Builder'!$A$2:$A$251,"Yes",'Scope Builder'!$C$2:$C$251,A24) -> 8690 | H24: Detailed MAO | K24: ='Flip Analysis'!C16 -> 115205.88
A25: Interior Finishes | B25: =SUMIFS('Scope Builder'!$U$2:$U$251,'Scope Builder'!$A$2:$A$251,"Yes",'Scope Builder'!$C$2:$C$251,A25) -> 5060 | H25: MAO Buffer | K25: ='Flip Analysis'!C17 -> 3205.8824
A26: Kitchen | B26: =SUMIFS('Scope Builder'!$U$2:$U$251,'Scope Builder'!$A$2:$A$251,"Yes",'Scope Builder'!$C$2:$C$251,A26) -> 26950
A27: Plumbing & Sewer | B27: =SUMIFS('Scope Builder'!$U$2:$U$251,'Scope Builder'!$A$2:$A$251,"Yes",'Scope Builder'!$C$2:$C$251,A27) -> 8250
A28: Roof & Attic | B28: =SUMIFS('Scope Builder'!$U$2:$U$251,'Scope Builder'!$A$2:$A$251,"Yes",'Scope Builder'!$C$2:$C$251,A28) -> 10890
A29: Soft Costs & Due Diligence | B29: =SUMIFS('Scope Builder'!$U$2:$U$251,'Scope Builder'!$A$2:$A$251,"Yes",'Scope Builder'!$C$2:$C$251,A29) -> 880
A30: Structure & Foundation | B30: =SUMIFS('Scope Builder'!$U$2:$U$251,'Scope Builder'!$A$2:$A$251,"Yes",'Scope Builder'!$C$2:$C$251,A30) -> 715
A31: Windows, Doors & Garage | B31: =SUMIFS('Scope Builder'!$U$2:$U$251,'Scope Builder'!$A$2:$A$251,"Yes",'Scope Builder'!$C$2:$C$251,A31) -> 5940
A44: PERFORMANCE KPIs
A45: ="MAO Buffer"&CHAR(10)&TEXT('Flip Analysis'!C17,"$#,##0;[Red]($#,##0);-") -> MAO Buffer $3,206 | D45: ="Rehab $ / sf"&CHAR(10)&TEXT('Flip Analysis'!C27,"$0.00")&"/sf" -> Rehab $ / sf $64.46/sf | G45: ="Contingency Remaining"&CHAR(10)&TEXT('Flip Analysis'!C30,"$#,##0;[Red]($#,##0);-") -> Contingency Remaining - | J45: ="Schedule Variance"&CHAR(10)&TEXT('Flip Analysis'!C24,"+0;-0;0")&" days" -> Schedule Variance +12 days
A49: ="Holding Cost / Day"&CHAR(10)&TEXT('Flip Analysis'!C26,"$#,##0.00;[Red]($#,##0.00);-") -> Holding Cost / Day $55.85 | D49: ="Profit / Day"&CHAR(10)&TEXT('Flip Analysis'!C40,"$#,##0;[Red]($#,##0);-") -> Profit / Day $336 | G49: ="ARV Variance"&CHAR(10)&TEXT('Flip Analysis'!C33,"$#,##0;[Red]($#,##0);-") -> ARV Variance $7,000 | J49: ="Actual-vs-Budget Variance"&CHAR(10)&TEXT('Flip Analysis'!C34,"$#,##0;[Red]($#,##0);-")&CHAR(10)&TEXT('Flip Analysis'!C35,"+0.0%;-0.0%;0.0%") -> Actual-vs-Budget Variance $3,110 +3.2%
A53: Actual-based KPIs use the blue Actual Performance Inputs on Project Inputs. Positive Schedule Variance and positive Actual-vs-Budget Variance indicate delay/overrun; positive MAO Buffer and ARV Variance are favorable.

Sheet Project Inputs
A1: HOUSE FLIP PROJECT INPUTS
A3: Property / Deal Assumptions | C3: Value | D3: Notes | F3: ACTUAL PERFORMANCE INPUTS
A4: Property Address | C4: EXAMPLE PROPERTY - St. Louis, MO 63116 | D4: WORKED EXAMPLE - replace with the subject property | F4: Planned Rehab Days | G4: 60 | H4: Example baseline; replace with plan
A5: City / ZIP | C5: St. Louis, MO 63116 | D5: Example market/ZIP | F5: Actual Rehab Days | G5: 72 | H5: Enter when rehab is complete / current actual
A6: Living Area (sf) | C6: 1500 | D6: Example living area | F6: Total Project Days | G6: 128 | H6: Acquisition through sale/close
A7: Beds / Baths | C7: 3 / 2 | D7: Example configuration | F7: Actual Rehab Cost | G7: 99800 | H7: Actual paid/committed rehab cost
A8: Purchase Price | C8: 112000 | D8: Illustrative acquisition price | F8: Actual Sale Price | G8: 292000 | H8: Enter final sale price when known
A9: After Repair Value (ARV) | C9: 285000 | D9: Illustrative comp-supported ARV
A10: Buying Closing Costs % | C10: 0.02 | D10: Example buying closing cost assumption
A11: Selling Costs % | C11: 0.08 | D11: Example selling cost assumption
A12: Holding Period (months) | C12: 5 | D12: Example acquisition-to-sale duration
A13: Monthly Holding Cost | C13: 1700 | D13: Interest + tax + insurance + utilities + lawn/security
A14: Financing / Points / Loan Fees | C14: 4500 | D14: Illustrative financing/points
A15: Default Rehab Contingency % | C15: 0.1 | D15: Example rehab contingency
A16: Target Profit | C16: 35000 | D16: Example minimum profit goal
A17: 70% Rule Benchmark | C17: 0.7 | D17: Quick-screening rule only
A19: WORKED EXAMPLE ACTIVE - replace blue/input cells for a real property.
A20: HOW TO USE
A21: 1 | B21: Enter or replace deal assumptions above.
A22: 2 | B22: Use Scope Builder: choose a Cost Code, paste the inspector/appraiser/designer note, enter quantity, priority and source.
A23: 3 | B23: Select cost basis: Low / Typical / High / Contractor Quote. Replace allowances with actual bids before purchase.
A24: 4 | B24: Dashboard and Flip Analysis update automatically for rows marked Include? = Yes.
A25: 5 | B25: Treat structural, active water, electrical safety, sewer, roof leaks and environmental issues as deal-risk items until professionally evaluated.

Sheet Scope Builder
A1: Include? | B1: Cost Code | C1: Category | D1: Trade | E1: Location / Room | F1: Inspector / Appraiser / Designer Note | G1: Work Type | H1: Source | I1: Severity | J1: Safety / Code? | K1: Priority | L1: Qty | M1: Unit | N1: Low | O1: Typical | P1: High | Q1: Contractor Quote (Total) | R1: Cost Basis | S1: Base Cost | T1: Contingency % | U1: Budgeted Cost | V1: Status | W1: Permit? | X1: Est. Days | Y1: ARV Impact | Z1: Value-Add Score (1-5) | AA1: Contractor | AB1: Dependency / Sequence | AC1: Notes | AD1: Material Qty | AE1: Material Unit Cost | AF1: Material Input Total | AG1: Labor Qty / Hours | AH1: Labor Unit Rate | AI1: Labor Input Total | AJ1: Equipment / Disposal | AK1: Permit / Other | AL1: Detailed Base Cost | AM1: Material Cost (Allocated) | AN1: Labor Cost (Allocated) | AO1: Other Cost (Allocated) | AP1: Contingency $ | AQ1: Material % | AR1: Labor % | AS1: Other % | AT1: Split Quality | AU1: Ballpark Basis | AV1: Ballpark Base Cost | AW1: Ballpark Budget incl. Contingency | AX1: Detailed Budget | AY1: Comparable Ballpark | AZ1: Variance $ | BA1: Variance % | BB1: Estimate Stage
A2: Yes | B2: SOFT-001 | C2: =IFERROR(VLOOKUP($B2,'Cost Library'!$A$2:$M$159,2,FALSE),"") -> Soft Costs & Due Diligence | D2: =IFERROR(VLOOKUP($B2,'Cost Library'!$A$2:$M$159,3,FALSE),"") -> Inspector | E2: Whole house | F2: General home inspection before contingency deadline | G2: =IFERROR(VLOOKUP($B2,'Cost Library'!$A$2:$M$159,5,FALSE),"") -> Inspection | H2: Home Inspector | I2: Medium | J2: No | K2: P1 - Before Offer | L2: 1 | M2: =IFERROR(VLOOKUP($B2,'Cost Library'!$A$2:$M$159,6,FALSE),"") -> project | N2: =IFERROR(VLOOKUP($B2,'Cost Library'!$A$2:$M$159,7,FALSE),0) -> 350 | O2: =IFERROR(VLOOKUP($B2,'Cost Library'!$A$2:$M$159,8,FALSE),0) -> 500 | P2: =IFERROR(VLOOKUP($B2,'Cost Library'!$A$2:$M$159,9,FALSE),0) -> 800 | Q2: 475 | R2: Contractor Quote | S2: =IF($A2<>"Yes",0,IF($R2="Detailed Breakdown",$AL2,IF($R2="Contractor Quote",$Q2,IF($R2="Low",$L2*$N2,IF($R2="High",$L2*$P2,$L2*$O2))))) -> 475 | T2: ='Project Inputs'!$C$15 -> 0.1 | U2: =IF($A2<>"Yes",0,$S2*(1+$T2)) -> 522.5 | V2: Complete | W2: =IFERROR(VLOOKUP($B2,'Cost Library'!$A$2:$M$159,10,FALSE),"") -> No | X2: 1 | Y2: 0 | Z2: 1 | AA2: Example Inspector | AB2: First due-diligence step | AC2: Illustrative quote | AF2: =IF(OR(AD2="",AE2=""),0,AD2*AE2) -> 0 | AI2: =IF(OR(AG2="",AH2=""),0,AG2*AH2) -> 0 | AL2: =SUM(AF2,AI2,AJ2,AK2) -> 0 | AM2: =IF($A2<>"Yes",0,IF($R2="Detailed Breakdown",$AF2,$S2*IFERROR(VLOOKUP($B2,'Cost Library'!$A$2:$Q$159,14,FALSE),0.4))) -> 0 | AN2: =IF($A2<>"Yes",0,IF($R2="Detailed Breakdown",$AI2,$S2*IFERROR(VLOOKUP($B2,'Cost Library'!$A$2:$Q$159,15,FALSE),0.5))) -> 0 | AO2: =IF($A2<>"Yes",0,IF($R2="Detailed Breakdown",$AJ2+$AK2,$S2*IFERROR(VLOOKUP($B2,'Cost Library'!$A$2:$Q$159,16,FALSE),0.1))) -> 475 | AP2: =IF($A2<>"Yes",0,$U2-$S2) -> 47.5 | AQ2: =IF($S2=0,0,$AM2/$S2) -> 0 | AR2: =IF($S2=0,0,$AN2/$S2) -> 0 | AS2: =IF($S2=0,0,$AO2/$S2) -> 1 | AT2: =IF($A2<>"Yes","",IF($R2="Detailed Breakdown","Detailed input",IF($R2="Contractor Quote","Estimated allocation - request vendor split","Planning allocation"))) -> Estimated allocation - request vendor split | AU2: Typical | AV2: =IF($A2<>"Yes",0,IF($AU2="Low",$L2*$N2,IF($AU2="High",$L2*$P2,$L2*$O2))) -> 500 | AW2: =IF($A2<>"Yes",0,$AV2*(1+$T2)) -> 550 | AX2: =IF(AND($A2="Yes",$AL2>0),$AL2*(1+$T2),0) -> 0 | AY2: =IF($AX2>0,$AW2,0) -> 0 | AZ2: =IF($AX2>0,$AX2-$AY2,0) -> 0 | BA2: =IF($AY2=0,0,$AZ2/$AY2) -> 0 | BB2: =IF($A2<>"Yes","",IF($Q2>0,"Quoted",IF($AL2>0,"Detailed","Ballpark"))) -> Quoted
A3: Yes | B3: SOFT-002 | C3: =IFERROR(VLOOKUP($B3,'Cost Library'!$A$2:$M$159,2,FALSE),"") -> Soft Costs & Due Diligence | D3: =IFERROR(VLOOKUP($B3,'Cost Library'!$A$2:$M$159,3,FALSE),"") -> Inspector | E3: Sewer lateral | F3: Camera scope of older sewer lateral | G3: =IFERROR(VLOOKUP($B3,'Cost Library'!$A$2:$M$159,5,FALSE),"") -> Inspection | H3: Home Inspector | I3: High | J3: No | K3: P1 - Before Offer | L3: 1 | M3: =IFERROR(VLOOKUP($B3,'Cost Library'!$A$2:$M$159,6,FALSE),"") -> project | N3: =IFERROR(VLOOKUP($B3,'Cost Library'!$A$2:$M$159,7,FALSE),0) -> 200 | O3: =IFERROR(VLOOKUP($B3,'Cost Library'!$A$2:$M$159,8,FALSE),0) -> 350 | P3: =IFERROR(VLOOKUP($B3,'Cost Library'!$A$2:$M$159,9,FALSE),0) -> 600 | Q3: 325 | R3: Contractor Quote | S3: =IF($A3<>"Yes",0,IF($R3="Detailed Breakdown",$AL3,IF($R3="Contractor Quote",$Q3,IF($R3="Low",$L3*$N3,IF($R3="High",$L3*$P3,$L3*$O3))))) -> 325 | T3: ='Project Inputs'!$C$15 -> 0.1 | U3: =IF($A3<>"Yes",0,$S3*(1+$T3)) -> 357.5 | V3: Complete | W3: =IFERROR(VLOOKUP($B3,'Cost Library'!$A$2:$M$159,10,FALSE),"") -> No | X3: 1 | Y3: 0 | Z3: 1 | AA3: Example Sewer Scope | AB3: After general inspection | AC3: Illustrative quote | AF3: =IF(OR(AD3="",AE3=""),0,AD3*AE3) -> 0 | AI3: =IF(OR(AG3="",AH3=""),0,AG3*AH3) -> 0 | AL3: =SUM(AF3,AI3,AJ3,AK3) -> 0 | AM3: =IF($A3<>"Yes",0,IF($R3="Detailed Breakdown",$AF3,$S3*IFERROR(VLOOKUP($B3,'Cost Library'!$A$2:$Q$159,14,FALSE),0.4))) -> 0 | AN3: =IF($A3<>"Yes",0,IF($R3="Detailed Breakdown",$AI3,$S3*IFERROR(VLOOKUP($B3,'Cost Library'!$A$2:$Q$159,15,FALSE),0.5))) -> 0 | AO3: =IF($A3<>"Yes",0,IF($R3="Detailed Breakdown",$AJ3+$AK3,$S3*IFERROR(VLOOKUP($B3,'Cost Library'!$A$2:$Q$159,16,FALSE),0.1))) -> 325 | AP3: =IF($A3<>"Yes",0,$U3-$S3) -> 32.5 | AQ3: =IF($S3=0,0,$AM3/$S3) -> 0 | AR3: =IF($S3=0,0,$AN3/$S3) -> 0 | AS3: =IF($S3=0,0,$AO3/$S3) -> 1 | AT3: =IF($A3<>"Yes","",IF($R3="Detailed Breakdown","Detailed input",IF($R3="Contractor Quote","Estimated allocation - request vendor split","Planning allocation"))) -> Estimated allocation - request vendor split | AU3: Typical | AV3: =IF($A3<>"Yes",0,IF($AU3="Low",$L3*$N3,IF($AU3="High",$L3*$P3,$L3*$O3))) -> 350 | AW3: =IF($A3<>"Yes",0,$AV3*(1+$T3)) -> 385 | AX3: =IF(AND($A3="Yes",$AL3>0),$AL3*(1+$T3),0) -> 0 | AY3: =IF($AX3>0,$AW3,0) -> 0 | AZ3: =IF($AX3>0,$AX3-$AY3,0) -> 0 | BA3: =IF($AY3=0,0,$AZ3/$AY3) -> 0 | BB3: =IF($A3<>"Yes","",IF($Q3>0,"Quoted",IF($AL3>0,"Detailed","Ballpark"))) -> Quoted
A4: Yes | B4: STR-001 | C4: =IFERROR(VLOOKUP($B4,'Cost Library'!$A$2:$M$159,2,FALSE),"") -> Structure & Foundation | D4: =IFERROR(VLOOKUP($B4,'Cost Library'!$A$2:$M$159,3,FALSE),"") -> Structural Engineer | E4: Basement | F4: Engineer review of stair-step cracking noted by inspector | G4: =IFERROR(VLOOKUP($B4,'Cost Library'!$A$2:$M$159,5,FALSE),"") -> Inspection | H4: Home Inspector | I4: Critical | J4: Yes | K4: P1 - Before Offer | L4: 1 | M4: =IFERROR(VLOOKUP($B4,'Cost Library'!$A$2:$M$159,6,FALSE),"") -> project | N4: =IFERROR(VLOOKUP($B4,'Cost Library'!$A$2:$M$159,7,FALSE),0) -> 400 | O4: =IFERROR(VLOOKUP($B4,'Cost Library'!$A$2:$M$159,8,FALSE),0) -> 750 | P4: =IFERROR(VLOOKUP($B4,'Cost Library'!$A$2:$M$159,9,FALSE),0) -> 1200 | Q4: 650 | R4: Contractor Quote | S4: =IF($A4<>"Yes",0,IF($R4="Detailed Breakdown",$AL4,IF($R4="Contractor Quote",$Q4,IF($R4="Low",$L4*$N4,IF($R4="High",$L4*$P4,$L4*$O4))))) -> 650 | T4: ='Project Inputs'!$C$15 -> 0.1 | U4: =IF($A4<>"Yes",0,$S4*(1+$T4)) -> 715 | V4: Complete | W4: =IFERROR(VLOOKUP($B4,'Cost Library'!$A$2:$M$159,10,FALSE),"") -> No | X4: 2 | Y4: 0 | Z4: 1 | AA4: Example Structural Engineer | AB4: Before committing to structural repairs | AC4: No stabilization assumed in example | AF4: =IF(OR(AD4="",AE4=""),0,AD4*AE4) -> 0 | AI4: =IF(OR(AG4="",AH4=""),0,AG4*AH4) -> 0 | AL4: =SUM(AF4,AI4,AJ4,AK4) -> 0 | AM4: =IF($A4<>"Yes",0,IF($R4="Detailed Breakdown",$AF4,$S4*IFERROR(VLOOKUP($B4,'Cost Library'!$A$2:$Q$159,14,FALSE),0.4))) -> 0 | AN4: =IF($A4<>"Yes",0,IF($R4="Detailed Breakdown",$AI4,$S4*IFERROR(VLOOKUP($B4,'Cost Library'!$A$2:$Q$159,15,FALSE),0.5))) -> 0 | AO4: =IF($A4<>"Yes",0,IF($R4="Detailed Breakdown",$AJ4+$AK4,$S4*IFERROR(VLOOKUP($B4,'Cost Library'!$A$2:$Q$159,16,FALSE),0.1))) -> 650 | AP4: =IF($A4<>"Yes",0,$U4-$S4) -> 65 | AQ4: =IF($S4=0,0,$AM4/$S4) -> 0 | AR4: =IF($S4=0,0,$AN4/$S4) -> 0 | AS4: =IF($S4=0,0,$AO4/$S4) -> 1 | AT4: =IF($A4<>"Yes","",IF($R4="Detailed Breakdown","Detailed input",IF($R4="Contractor Quote","Estimated allocation - request vendor split","Planning allocation"))) -> Estimated allocation - request vendor split | AU4: Typical | AV4: =IF($A4<>"Yes",0,IF($AU4="Low",$L4*$N4,IF($AU4="High",$L4*$P4,$L4*$O4))) -> 750 | AW4: =IF($A4<>"Yes",0,$AV4*(1+$T4)) -> 825 | AX4: =IF(AND($A4="Yes",$AL4>0),$AL4*(1+$T4),0) -> 0 | AY4: =IF($AX4>0,$AW4,0) -> 0 | AZ4: =IF($AX4>0,$AX4-$AY4,0) -> 0 | BA4: =IF($AY4=0,0,$AZ4/$AY4) -> 0 | BB4: =IF($A4<>"Yes","",IF($Q4>0,"Quoted",IF($AL4>0,"Detailed","Ballpark"))) -> Quoted
A5: Yes | B5: ROF-001 | C5: =IFERROR(VLOOKUP($B5,'Cost Library'!$A$2:$M$159,2,FALSE),"") -> Roof & Attic | D5: =IFERROR(VLOOKUP($B5,'Cost Library'!$A$2:$M$159,3,FALSE),"") -> Roofing | E5: Roof | F5: Replace aging asphalt-shingle roof; include tear-off and disposal | G5: =IFERROR(VLOOKUP($B5,'Cost Library'!$A$2:$M$159,5,FALSE),"") -> Replace | H5: Home Inspector | I5: Critical | J5: Yes | K5: P1 - Before Offer | L5: 1 | M5: =IFERROR(VLOOKUP($B5,'Cost Library'!$A$2:$M$159,6,FALSE),"") -> project | N5: =IFERROR(VLOOKUP($B5,'Cost Library'!$A$2:$M$159,7,FALSE),0) -> 5433 | O5: =IFERROR(VLOOKUP($B5,'Cost Library'!$A$2:$M$159,8,FALSE),0) -> 8155 | P5: =IFERROR(VLOOKUP($B5,'Cost Library'!$A$2:$M$159,9,FALSE),0) -> 11032 | R5: Detailed Breakdown | S5: =IF($A5<>"Yes",0,IF($R5="Detailed Breakdown",$AL5,IF($R5="Contractor Quote",$Q5,IF($R5="Low",$L5*$N5,IF($R5="High",$L5*$P5,$L5*$O5))))) -> 9900 | T5: ='Project Inputs'!$C$15 -> 0.1 | U5: =IF($A5<>"Yes",0,$S5*(1+$T5)) -> 10890 | V5: Quoted | W5: =IFERROR(VLOOKUP($B5,'Cost Library'!$A$2:$M$159,10,FALSE),"") -> Yes | X5: 4 | Y5: 12000 | Z5: 3 | AA5: Example Roofer | AB5: Complete before interior moisture repairs | AC5: Detailed example is above ballpark | AD5: 1 | AE5: 4200 | AF5: =IF(OR(AD5="",AE5=""),0,AD5*AE5) -> 4200 | AG5: 1 | AH5: 4000 | AI5: =IF(OR(AG5="",AH5=""),0,AG5*AH5) -> 4000 | AJ5: 1400 | AK5: 300 | AL5: =SUM(AF5,AI5,AJ5,AK5) -> 9900 | AM5: =IF($A5<>"Yes",0,IF($R5="Detailed Breakdown",$AF5,$S5*IFERROR(VLOOKUP($B5,'Cost Library'!$A$2:$Q$159,14,FALSE),0.4))) -> 4200 | AN5: =IF($A5<>"Yes",0,IF($R5="Detailed Breakdown",$AI5,$S5*IFERROR(VLOOKUP($B5,'Cost Library'!$A$2:$Q$159,15,FALSE),0.5))) -> 4000 | AO5: =IF($A5<>"Yes",0,IF($R5="Detailed Breakdown",$AJ5+$AK5,$S5*IFERROR(VLOOKUP($B5,'Cost Library'!$A$2:$Q$159,16,FALSE),0.1))) -> 1700 | AP5: =IF($A5<>"Yes",0,$U5-$S5) -> 990 | AQ5: =IF($S5=0,0,$AM5/$S5) -> 0.42424242 | AR5: =IF($S5=0,0,$AN5/$S5) -> 0.4040404 | AS5: =IF($S5=0,0,$AO5/$S5) -> 0.17171717 | AT5: =IF($A5<>"Yes","",IF($R5="Detailed Breakdown","Detailed input",IF($R5="Contractor Quote","Estimated allocation - request vendor split","Planning allocation"))) -> Detailed input | AU5: Typical | AV5: =IF($A5<>"Yes",0,IF($AU5="Low",$L5*$N5,IF($AU5="High",$L5*$P5,$L5*$O5))) -> 8155 | AW5: =IF($A5<>"Yes",0,$AV5*(1+$T5)) -> 8970.5 | AX5: =IF(AND($A5="Yes",$AL5>0),$AL5*(1+$T5),0) -> 10890 | AY5: =IF($AX5>0,$AW5,0) -> 8970.5 | AZ5: =IF($AX5>0,$AX5-$AY5,0) -> 1919.5 | BA5: =IF($AY5=0,0,$AZ5/$AY5) -> 0.21397915 | BB5: =IF($A5<>"Yes","",IF($Q5>0,"Quoted",IF($AL5>0,"Detailed","Ballpark"))) -> Detailed
A6: Yes | B6: ELE-001 | C6: =IFERROR(VLOOKUP($B6,'Cost Library'!$A$2:$M$159,2,FALSE),"") -> Electrical | D6: =IFERROR(VLOOKUP($B6,'Cost Library'!$A$2:$M$159,3,FALSE),"") -> Electrician | E6: Basement / service | F6: Replace obsolete electrical panel and correct grounding/labeling | G6: =IFERROR(VLOOKUP($B6,'Cost Library'!$A$2:$M$159,5,FALSE),"") -> Replace | H6: Home Inspector | I6: Critical | J6: Yes | K6: P1 - Before Offer | L6: 1 | M6: =IFERROR(VLOOKUP($B6,'Cost Library'!$A$2:$M$159,6,FALSE),"") -> project | N6: =IFERROR(VLOOKUP($B6,'Cost Library'!$A$2:$M$159,7,FALSE),0) -> 1800 | O6: =IFERROR(VLOOKUP($B6,'Cost Library'!$A$2:$M$159,8,FALSE),0) -> 3000 | P6: =IFERROR(VLOOKUP($B6,'Cost Library'!$A$2:$M$159,9,FALSE),0) -> 5000 | R6: Detailed Breakdown | S6: =IF($A6<>"Yes",0,IF($R6="Detailed Breakdown",$AL6,IF($R6="Contractor Quote",$Q6,IF($R6="Low",$L6*$N6,IF($R6="High",$L6*$P6,$L6*$O6))))) -> 3600 | T6: ='Project Inputs'!$C$15 -> 0.1 | U6: =IF($A6<>"Yes",0,$S6*(1+$T6)) -> 3960 | V6: Quoted | W6: =IFERROR(VLOOKUP($B6,'Cost Library'!$A$2:$M$159,10,FALSE),"") -> Yes | X6: 2 | Y6: 5000 | Z6: 2 | AA6: Example Electrician | AB6: Before finish work | AC6: Permit allowance included | AD6: 1 | AE6: 1450 | AF6: =IF(OR(AD6="",AE6=""),0,AD6*AE6) -> 1450 | AG6: 1 | AH6: 1800 | AI6: =IF(OR(AG6="",AH6=""),0,AG6*AH6) -> 1800 | AJ6: 0 | AK6: 350 | AL6: =SUM(AF6,AI6,AJ6,AK6) -> 3600 | AM6: =IF($A6<>"Yes",0,IF($R6="Detailed Breakdown",$AF6,$S6*IFERROR(VLOOKUP($B6,'Cost Library'!$A$2:$Q$159,14,FALSE),0.4))) -> 1450 | AN6: =IF($A6<>"Yes",0,IF($R6="Detailed Breakdown",$AI6,$S6*IFERROR(VLOOKUP($B6,'Cost Library'!$A$2:$Q$159,15,FALSE),0.5))) -> 1800 | AO6: =IF($A6<>"Yes",0,IF($R6="Detailed Breakdown",$AJ6+$AK6,$S6*IFERROR(VLOOKUP($B6,'Cost Library'!$A$2:$Q$159,16,FALSE),0.1))) -> 350 | AP6: =IF($A6<>"Yes",0,$U6-$S6) -> 360 | AQ6: =IF($S6=0,0,$AM6/$S6) -> 0.40277778 | AR6: =IF($S6=0,0,$AN6/$S6) -> 0.5 | AS6: =IF($S6=0,0,$AO6/$S6) -> 0.097222222 | AT6: =IF($A6<>"Yes","",IF($R6="Detailed Breakdown","Detailed input",IF($R6="Contractor Quote","Estimated allocation - request vendor split","Planning allocation"))) -> Detailed input | AU6: Typical | AV6: =IF($A6<>"Yes",0,IF($AU6="Low",$L6*$N6,IF($AU6="High",$L6*$P6,$L6*$O6))) -> 3000 | AW6: =IF($A6<>"Yes",0,$AV6*(1+$T6)) -> 3300 | AX6: =IF(AND($A6="Yes",$AL6>0),$AL6*(1+$T6),0) -> 3960 | AY6: =IF($AX6>0,$AW6,0) -> 3300 | AZ6: =IF($AX6>0,$AX6-$AY6,0) -> 660 | BA6: =IF($AY6=0,0,$AZ6/$AY6) -> 0.2 | BB6: =IF($A6<>"Yes","",IF($Q6>0,"Quoted",IF($AL6>0,"Detailed","Ballpark"))) -> Detailed
A7: Yes | B7: PLB-009 | C7: =IFERROR(VLOOKUP($B7,'Cost Library'!$A$2:$M$159,2,FALSE),"") -> Plumbing & Sewer | D7: =IFERROR(VLOOKUP($B7,'Cost Library'!$A$2:$M$159,3,FALSE),"") -> Plumber | E7: Front yard / sewer | F7: Spot repair of sewer lateral after root intrusion found on scope | G7: =IFERROR(VLOOKUP($B7,'Cost Library'!$A$2:$M$159,5,FALSE),"") -> Repair | H7: Specialist | I7: Critical | J7: Yes | K7: P1 - Before Offer | L7: 1 | M7: =IFERROR(VLOOKUP($B7,'Cost Library'!$A$2:$M$159,6,FALSE),"") -> project | N7: =IFERROR(VLOOKUP($B7,'Cost Library'!$A$2:$M$159,7,FALSE),0) -> 1500 | O7: =IFERROR(VLOOKUP($B7,'Cost Library'!$A$2:$M$159,8,FALSE),0) -> 5000 | P7: =IFERROR(VLOOKUP($B7,'Cost Library'!$A$2:$M$159,9,FALSE),0) -> 12000 | R7: Detailed Breakdown | S7: =IF($A7<>"Yes",0,IF($R7="Detailed Breakdown",$AL7,IF($R7="Contractor Quote",$Q7,IF($R7="Low",$L7*$N7,IF($R7="High",$L7*$P7,$L7*$O7))))) -> 7500 | T7: ='Project Inputs'!$C$15 -> 0.1 | U7: =IF($A7<>"Yes",0,$S7*(1+$T7)) -> 8250 | V7: Quoted | W7: =IFERROR(VLOOKUP($B7,'Cost Library'!$A$2:$M$159,10,FALSE),"") -> Yes | X7: 3 | Y7: 0 | Z7: 1 | AA7: Example Plumber | AB7: After sewer camera | AC7: Excavation included; high uncertainty item | AD7: 1 | AE7: 1800 | AF7: =IF(OR(AD7="",AE7=""),0,AD7*AE7) -> 1800 | AG7: 1 | AH7: 3000 | AI7: =IF(OR(AG7="",AH7=""),0,AG7*AH7) -> 3000 | AJ7: 2200 | AK7: 500 | AL7: =SUM(AF7,AI7,AJ7,AK7) -> 7500 | AM7: =IF($A7<>"Yes",0,IF($R7="Detailed Breakdown",$AF7,$S7*IFERROR(VLOOKUP($B7,'Cost Library'!$A$2:$Q$159,14,FALSE),0.4))) -> 1800 | AN7: =IF($A7<>"Yes",0,IF($R7="Detailed Breakdown",$AI7,$S7*IFERROR(VLOOKUP($B7,'Cost Library'!$A$2:$Q$159,15,FALSE),0.5))) -> 3000 | AO7: =IF($A7<>"Yes",0,IF($R7="Detailed Breakdown",$AJ7+$AK7,$S7*IFERROR(VLOOKUP($B7,'Cost Library'!$A$2:$Q$159,16,FALSE),0.1))) -> 2700 | AP7: =IF($A7<>"Yes",0,$U7-$S7) -> 750 | AQ7: =IF($S7=0,0,$AM7/$S7) -> 0.24 | AR7: =IF($S7=0,0,$AN7/$S7) -> 0.4 | AS7: =IF($S7=0,0,$AO7/$S7) -> 0.36 | AT7: =IF($A7<>"Yes","",IF($R7="Detailed Breakdown","Detailed input",IF($R7="Contractor Quote","Estimated allocation - request vendor split","Planning allocation"))) -> Detailed input | AU7: Typical | AV7: =IF($A7<>"Yes",0,IF($AU7="Low",$L7*$N7,IF($AU7="High",$L7*$P7,$L7*$O7))) -> 5000 | AW7: =IF($A7<>"Yes",0,$AV7*(1+$T7)) -> 5500 | AX7: =IF(AND($A7="Yes",$AL7>0),$AL7*(1+$T7),0) -> 8250 | AY7: =IF($AX7>0,$AW7,0) -> 5500 | AZ7: =IF($AX7>0,$AX7-$AY7,0) -> 2750 | BA7: =IF($AY7=0,0,$AZ7/$AY7) -> 0.5 | BB7: =IF($A7<>"Yes","",IF($Q7>0,"Quoted",IF($AL7>0,"Detailed","Ballpark"))) -> Detailed
A8: Yes | B8: HVAC-001 | C8: =IFERROR(VLOOKUP($B8,'Cost Library'!$A$2:$M$159,2,FALSE),"") -> HVAC | D8: =IFERROR(VLOOKUP($B8,'Cost Library'!$A$2:$M$159,3,FALSE),"") -> HVAC | E8: Whole house | F8: Replace end-of-life furnace/AC system | G8: =IFERROR(VLOOKUP($B8,'Cost Library'!$A$2:$M$159,5,FALSE),"") -> Replace | H8: Home Inspector | I8: High | J8: No | K8: P2 - Before Sale | L8: 1 | M8: =IFERROR(VLOOKUP($B8,'Cost Library'!$A$2:$M$159,6,FALSE),"") -> project | N8: =IFERROR(VLOOKUP($B8,'Cost Library'!$A$2:$M$159,7,FALSE),0) -> 4755 | O8: =IFERROR(VLOOKUP($B8,'Cost Library'!$A$2:$M$159,8,FALSE),0) -> 7133 | P8: =IFERROR(VLOOKUP($B8,'Cost Library'!$A$2:$M$159,9,FALSE),0) -> 11888 | R8: Detailed Breakdown | S8: =IF($A8<>"Yes",0,IF($R8="Detailed Breakdown",$AL8,IF($R8="Contractor Quote",$Q8,IF($R8="Low",$L8*$N8,IF($R8="High",$L8*$P8,$L8*$O8))))) -> 7900 | T8: ='Project Inputs'!$C$15 -> 0.1 | U8: =IF($A8<>"Yes",0,$S8*(1+$T8)) -> 8690 | V8: Quoted | W8: =IFERROR(VLOOKUP($B8,'Cost Library'!$A$2:$M$159,10,FALSE),"") -> Yes | X8: 3 | Y8: 8000 | Z8: 3 | AA8: Example HVAC Contractor | AB8: Before final paint touch-up | AC8: Illustrative installed-system breakdown | AD8: 1 | AE8: 4600 | AF8: =IF(OR(AD8="",AE8=""),0,AD8*AE8) -> 4600 | AG8: 1 | AH8: 2800 | AI8: =IF(OR(AG8="",AH8=""),0,AG8*AH8) -> 2800 | AJ8: 300 | AK8: 200 | AL8: =SUM(AF8,AI8,AJ8,AK8) -> 7900 | AM8: =IF($A8<>"Yes",0,IF($R8="Detailed Breakdown",$AF8,$S8*IFERROR(VLOOKUP($B8,'Cost Library'!$A$2:$Q$159,14,FALSE),0.4))) -> 4600 | AN8: =IF($A8<>"Yes",0,IF($R8="Detailed Breakdown",$AI8,$S8*IFERROR(VLOOKUP($B8,'Cost Library'!$A$2:$Q$159,15,FALSE),0.5))) -> 2800 | AO8: =IF($A8<>"Yes",0,IF($R8="Detailed Breakdown",$AJ8+$AK8,$S8*IFERROR(VLOOKUP($B8,'Cost Library'!$A$2:$Q$159,16,FALSE),0.1))) -> 500 | AP8: =IF($A8<>"Yes",0,$U8-$S8) -> 790 | AQ8: =IF($S8=0,0,$AM8/$S8) -> 0.58227848 | AR8: =IF($S8=0,0,$AN8/$S8) -> 0.35443038 | AS8: =IF($S8=0,0,$AO8/$S8) -> 0.063291139 | AT8: =IF($A8<>"Yes","",IF($R8="Detailed Breakdown","Detailed input",IF($R8="Contractor Quote","Estimated allocation - request vendor split","Planning allocation"))) -> Detailed input | AU8: Typical | AV8: =IF($A8<>"Yes",0,IF($AU8="Low",$L8*$N8,IF($AU8="High",$L8*$P8,$L8*$O8))) -> 7133 | AW8: =IF($A8<>"Yes",0,$AV8*(1+$T8)) -> 7846.3 | AX8: =IF(AND($A8="Yes",$AL8>0),$AL8*(1+$T8),0) -> 8690 | AY8: =IF($AX8>0,$AW8,0) -> 7846.3 | AZ8: =IF($AX8>0,$AX8-$AY8,0) -> 843.7 | BA8: =IF($AY8=0,0,$AZ8/$AY8) -> 0.10752839 | BB8: =IF($A8<>"Yes","",IF($Q8>0,"Quoted",IF($AL8>0,"Detailed","Ballpark"))) -> Detailed
A9: Yes | B9: INT-004 | C9: =IFERROR(VLOOKUP($B9,'Cost Library'!$A$2:$M$159,2,FALSE),"") -> Interior Finishes | D9: =IFERROR(VLOOKUP($B9,'Cost Library'!$A$2:$M$159,3,FALSE),"") -> Painting | E9: Whole house | F9: Neutral interior repaint for resale | G9: =IFERROR(VLOOKUP($B9,'Cost Library'!$A$2:$M$159,5,FALSE),"") -> Renovation | H9: Interior Designer | I9: Low | J9: No | K9: P3 - Value Add | L9: 1500 | M9: =IFERROR(VLOOKUP($B9,'Cost Library'!$A$2:$M$159,6,FALSE),"") -> sf | N9: =IFERROR(VLOOKUP($B9,'Cost Library'!$A$2:$M$159,7,FALSE),0) -> 1.5 | O9: =IFERROR(VLOOKUP($B9,'Cost Library'!$A$2:$M$159,8,FALSE),0) -> 3 | P9: =IFERROR(VLOOKUP($B9,'Cost Library'!$A$2:$M$159,9,FALSE),0) -> 5 | R9: Detailed Breakdown | S9: =IF($A9<>"Yes",0,IF($R9="Detailed Breakdown",$AL9,IF($R9="Contractor Quote",$Q9,IF($R9="Low",$L9*$N9,IF($R9="High",$L9*$P9,$L9*$O9))))) -> 4600 | T9: ='Project Inputs'!$C$15 -> 0.1 | U9: =IF($A9<>"Yes",0,$S9*(1+$T9)) -> 5060 | V9: Approved | W9: =IFERROR(VLOOKUP($B9,'Cost Library'!$A$2:$M$159,10,FALSE),"") -> No | X9: 5 | Y9: 8000 | Z9: 4 | AA9: Example Painting Crew | AB9: After major electrical/plumbing work | AC9: 35 gal paint/supplies + labor example | AD9: 35 | AE9: 45 | AF9: =IF(OR(AD9="",AE9=""),0,AD9*AE9) -> 1575 | AG9: 45 | AH9: 60 | AI9: =IF(OR(AG9="",AH9=""),0,AG9*AH9) -> 2700 | AJ9: 200 | AK9: 125 | AL9: =SUM(AF9,AI9,AJ9,AK9) -> 4600 | AM9: =IF($A9<>"Yes",0,IF($R9="Detailed Breakdown",$AF9,$S9*IFERROR(VLOOKUP($B9,'Cost Library'!$A$2:$Q$159,14,FALSE),0.4))) -> 1575 | AN9: =IF($A9<>"Yes",0,IF($R9="Detailed Breakdown",$AI9,$S9*IFERROR(VLOOKUP($B9,'Cost Library'!$A$2:$Q$159,15,FALSE),0.5))) -> 2700 | AO9: =IF($A9<>"Yes",0,IF($R9="Detailed Breakdown",$AJ9+$AK9,$S9*IFERROR(VLOOKUP($B9,'Cost Library'!$A$2:$Q$159,16,FALSE),0.1))) -> 325 | AP9: =IF($A9<>"Yes",0,$U9-$S9) -> 460 | AQ9: =IF($S9=0,0,$AM9/$S9) -> 0.3423913 | AR9: =IF($S9=0,0,$AN9/$S9) -> 0.58695652 | AS9: =IF($S9=0,0,$AO9/$S9) -> 0.070652174 | AT9: =IF($A9<>"Yes","",IF($R9="Detailed Breakdown","Detailed input",IF($R9="Contractor Quote","Estimated allocation - request vendor split","Planning allocation"))) -> Detailed input | AU9: Typical | AV9: =IF($A9<>"Yes",0,IF($AU9="Low",$L9*$N9,IF($AU9="High",$L9*$P9,$L9*$O9))) -> 4500 | AW9: =IF($A9<>"Yes",0,$AV9*(1+$T9)) -> 4950 | AX9: =IF(AND($A9="Yes",$AL9>0),$AL9*(1+$T9),0) -> 5060 | AY9: =IF($AX9>0,$AW9,0) -> 4950 | AZ9: =IF($AX9>0,$AX9-$AY9,0) -> 110 | BA9: =IF($AY9=0,0,$AZ9/$AY9) -> 0.022222222 | BB9: =IF($A9<>"Yes","",IF($Q9>0,"Quoted",IF($AL9>0,"Detailed","Ballpark"))) -> Detailed
A10: Yes | B10: FLR-001 | C10: =IFERROR(VLOOKUP($B10,'Cost Library'!$A$2:$M$159,2,FALSE),"") -> Flooring | D10: =IFERROR(VLOOKUP($B10,'Cost Library'!$A$2:$M$159,3,FALSE),"") -> Flooring | E10: Living areas / bedrooms | F10: Install LVP; 1,200 sf coverage plus ~10% material waste | G10: =IFERROR(VLOOKUP($B10,'Cost Library'!$A$2:$M$159,5,FALSE),"") -> Renovation | H10: Interior Designer | I10: Low | J10: No | K10: P3 - Value Add | L10: 1200 | M10: =IFERROR(VLOOKUP($B10,'Cost Library'!$A$2:$M$159,6,FALSE),"") -> sf | N10: =IFERROR(VLOOKUP($B10,'Cost Library'!$A$2:$M$159,7,FALSE),0) -> 3 | O10: =IFERROR(VLOOKUP($B10,'Cost Library'!$A$2:$M$159,8,FALSE),0) -> 6 | P10: =IFERROR(VLOOKUP($B10,'Cost Library'!$A$2:$M$159,9,FALSE),0) -> 10 | R10: Detailed Breakdown | S10: =IF($A10<>"Yes",0,IF($R10="Detailed Breakdown",$AL10,IF($R10="Contractor Quote",$Q10,IF($R10="Low",$L10*$N10,IF($R10="High",$L10*$P10,$L10*$O10))))) -> 7600 | T10: ='Project Inputs'!$C$15 -> 0.1 | U10: =IF($A10<>"Yes",0,$S10*(1+$T10)) -> 8360 | V10: Approved | W10: =IFERROR(VLOOKUP($B10,'Cost Library'!$A$2:$M$159,10,FALSE),"") -> No | X10: 4 | Y10: 10000 | Z10: 5 | AA10: Example Flooring Crew | AB10: After painting; before final trim | AC10: Detailed takeoff uses 1,320 sf material | AD10: 1320 | AE10: 2.95 | AF10: =IF(OR(AD10="",AE10=""),0,AD10*AE10) -> 3894 | AG10: 1200 | AH10: 2.4 | AI10: =IF(OR(AG10="",AH10=""),0,AG10*AH10) -> 2880 | AJ10: 600 | AK10: 226 | AL10: =SUM(AF10,AI10,AJ10,AK10) -> 7600 | AM10: =IF($A10<>"Yes",0,IF($R10="Detailed Breakdown",$AF10,$S10*IFERROR(VLOOKUP($B10,'Cost Library'!$A$2:$Q$159,14,FALSE),0.4))) -> 3894 | AN10: =IF($A10<>"Yes",0,IF($R10="Detailed Breakdown",$AI10,$S10*IFERROR(VLOOKUP($B10,'Cost Library'!$A$2:$Q$159,15,FALSE),0.5))) -> 2880 | AO10: =IF($A10<>"Yes",0,IF($R10="Detailed Breakdown",$AJ10+$AK10,$S10*IFERROR(VLOOKUP($B10,'Cost Library'!$A$2:$Q$159,16,FALSE),0.1))) -> 826 | AP10: =IF($A10<>"Yes",0,$U10-$S10) -> 760 | AQ10: =IF($S10=0,0,$AM10/$S10) -> 0.51236842 | AR10: =IF($S10=0,0,$AN10/$S10) -> 0.37894737 | AS10: =IF($S10=0,0,$AO10/$S10) -> 0.10868421 | AT10: =IF($A10<>"Yes","",IF($R10="Detailed Breakdown","Detailed input",IF($R10="Contractor Quote","Estimated allocation - request vendor split","Planning allocation"))) -> Detailed input | AU10: Typical | AV10: =IF($A10<>"Yes",0,IF($AU10="Low",$L10*$N10,IF($AU10="High",$L10*$P10,$L10*$O10))) -> 7200 | AW10: =IF($A10<>"Yes",0,$AV10*(1+$T10)) -> 7920 | AX10: =IF(AND($A10="Yes",$AL10>0),$AL10*(1+$T10),0) -> 8360 | AY10: =IF($AX10>0,$AW10,0) -> 7920 | AZ10: =IF($AX10>0,$AX10-$AY10,0) -> 440 | BA10: =IF($AY10=0,0,$AZ10/$AY10) -> 0.055555556 | BB10: =IF($A10<>"Yes","",IF($Q10>0,"Quoted",IF($AL10>0,"Detailed","Ballpark"))) -> Detailed
A11: Yes | B11: KIT-001 | C11: =IFERROR(VLOOKUP($B11,'Cost Library'!$A$2:$M$159,2,FALSE),"") -> Kitchen | D11: =IFERROR(VLOOKUP($B11,'Cost Library'!$A$2:$M$159,3,FALSE),"") -> General Contractor | E11: Kitchen | F11: Mid-range flip kitchen: cabinets, counters, appliances, lighting and finish work | G11: =IFERROR(VLOOKUP($B11,'Cost Library'!$A$2:$M$159,5,FALSE),"") -> Renovation | H11: Interior Designer | I11: Medium | J11: No | K11: P3 - Value Add | L11: 1 | M11: =IFERROR(VLOOKUP($B11,'Cost Library'!$A$2:$M$159,6,FALSE),"") -> project | N11: =IFERROR(VLOOKUP($B11,'Cost Library'!$A$2:$M$159,7,FALSE),0) -> 13800 | O11: =IFERROR(VLOOKUP($B11,'Cost Library'!$A$2:$M$159,8,FALSE),0) -> 26000 | P11: =IFERROR(VLOOKUP($B11,'Cost Library'!$A$2:$M$159,9,FALSE),0) -> 38600 | R11: Detailed Breakdown | S11: =IF($A11<>"Yes",0,IF($R11="Detailed Breakdown",$AL11,IF($R11="Contractor Quote",$Q11,IF($R11="Low",$L11*$N11,IF($R11="High",$L11*$P11,$L11*$O11))))) -> 24500 | T11: ='Project Inputs'!$C$15 -> 0.1 | U11: =IF($A11<>"Yes",0,$S11*(1+$T11)) -> 26950 | V11: Approved | W11: =IFERROR(VLOOKUP($B11,'Cost Library'!$A$2:$M$159,10,FALSE),"") -> Sometimes | X11: 14 | Y11: 25000 | Z11: 5 | AA11: Example GC / Kitchen Crew | AB11: Rough plumbing/electrical before cabinets | AC11: Illustrative bundled material and labor | AD11: 1 | AE11: 14000 | AF11: =IF(OR(AD11="",AE11=""),0,AD11*AE11) -> 14000 | AG11: 1 | AH11: 8000 | AI11: =IF(OR(AG11="",AH11=""),0,AG11*AH11) -> 8000 | AJ11: 1200 | AK11: 1300 | AL11: =SUM(AF11,AI11,AJ11,AK11) -> 24500 | AM11: =IF($A11<>"Yes",0,IF($R11="Detailed Breakdown",$AF11,$S11*IFERROR(VLOOKUP($B11,'Cost Library'!$A$2:$Q$159,14,FALSE),0.4))) -> 14000 | AN11: =IF($A11<>"Yes",0,IF($R11="Detailed Breakdown",$AI11,$S11*IFERROR(VLOOKUP($B11,'Cost Library'!$A$2:$Q$159,15,FALSE),0.5))) -> 8000 | AO11: =IF($A11<>"Yes",0,IF($R11="Detailed Breakdown",$AJ11+$AK11,$S11*IFERROR(VLOOKUP($B11,'Cost Library'!$A$2:$Q$159,16,FALSE),0.1))) -> 2500 | AP11: =IF($A11<>"Yes",0,$U11-$S11) -> 2450 | AQ11: =IF($S11=0,0,$AM11/$S11) -> 0.57142857 | AR11: =IF($S11=0,0,$AN11/$S11) -> 0.32653061 | AS11: =IF($S11=0,0,$AO11/$S11) -> 0.10204082 | AT11: =IF($A11<>"Yes","",IF($R11="Detailed Breakdown","Detailed input",IF($R11="Contractor Quote","Estimated allocation - request vendor split","Planning allocation"))) -> Detailed input | AU11: Typical | AV11: =IF($A11<>"Yes",0,IF($AU11="Low",$L11*$N11,IF($AU11="High",$L11*$P11,$L11*$O11))) -> 26000 | AW11: =IF($A11<>"Yes",0,$AV11*(1+$T11)) -> 28600 | AX11: =IF(AND($A11="Yes",$AL11>0),$AL11*(1+$T11),0) -> 26950 | AY11: =IF($AX11>0,$AW11,0) -> 28600 | AZ11: =IF($AX11>0,$AX11-$AY11,0) -> -1650 | BA11: =IF($AY11=0,0,$AZ11/$AY11) -> -0.057692308 | BB11: =IF($A11<>"Yes","",IF($Q11>0,"Quoted",IF($AL11>0,"Detailed","Ballpark"))) -> Detailed
A12: Yes | B12: BAT-001 | C12: =IFERROR(VLOOKUP($B12,'Cost Library'!$A$2:$M$159,2,FALSE),"") -> Bathrooms | D12: =IFERROR(VLOOKUP($B12,'Cost Library'!$A$2:$M$159,3,FALSE),"") -> General Contractor | E12: Main bathroom | F12: Full bath refresh with waterproofing, vanity, fixtures, tile and paint | G12: =IFERROR(VLOOKUP($B12,'Cost Library'!$A$2:$M$159,5,FALSE),"") -> Renovation | H12: Interior Designer | I12: Medium | J12: No | K12: P3 - Value Add | L12: 1 | M12: =IFERROR(VLOOKUP($B12,'Cost Library'!$A$2:$M$159,6,FALSE),"") -> bath | N12: =IFERROR(VLOOKUP($B12,'Cost Library'!$A$2:$M$159,7,FALSE),0) -> 6423 | O12: =IFERROR(VLOOKUP($B12,'Cost Library'!$A$2:$M$159,8,FALSE),0) -> 11246 | P12: =IFERROR(VLOOKUP($B12,'Cost Library'!$A$2:$M$159,9,FALSE),0) -> 16519 | R12: Detailed Breakdown | S12: =IF($A12<>"Yes",0,IF($R12="Detailed Breakdown",$AL12,IF($R12="Contractor Quote",$Q12,IF($R12="Low",$L12*$N12,IF($R12="High",$L12*$P12,$L12*$O12))))) -> 12700 | T12: ='Project Inputs'!$C$15 -> 0.1 | U12: =IF($A12<>"Yes",0,$S12*(1+$T12)) -> 13970 | V12: Approved | W12: =IFERROR(VLOOKUP($B12,'Cost Library'!$A$2:$M$159,10,FALSE),"") -> Sometimes | X12: 8 | Y12: 15000 | Z12: 5 | AA12: Example Bath Contractor | AB12: After rough plumbing/electrical | AC12: Detailed estimate slightly above ballpark | AD12: 1 | AE12: 6800 | AF12: =IF(OR(AD12="",AE12=""),0,AD12*AE12) -> 6800 | AG12: 1 | AH12: 4600 | AI12: =IF(OR(AG12="",AH12=""),0,AG12*AH12) -> 4600 | AJ12: 700 | AK12: 600 | AL12: =SUM(AF12,AI12,AJ12,AK12) -> 12700 | AM12: =IF($A12<>"Yes",0,IF($R12="Detailed Breakdown",$AF12,$S12*IFERROR(VLOOKUP($B12,'Cost Library'!$A$2:$Q$159,14,FALSE),0.4))) -> 6800 | AN12: =IF($A12<>"Yes",0,IF($R12="Detailed Breakdown",$AI12,$S12*IFERROR(VLOOKUP($B12,'Cost Library'!$A$2:$Q$159,15,FALSE),0.5))) -> 4600 | AO12: =IF($A12<>"Yes",0,IF($R12="Detailed Breakdown",$AJ12+$AK12,$S12*IFERROR(VLOOKUP($B12,'Cost Library'!$A$2:$Q$159,16,FALSE),0.1))) -> 1300 | AP12: =IF($A12<>"Yes",0,$U12-$S12) -> 1270 | AQ12: =IF($S12=0,0,$AM12/$S12) -> 0.53543307 | AR12: =IF($S12=0,0,$AN12/$S12) -> 0.36220472 | AS12: =IF($S12=0,0,$AO12/$S12) -> 0.1023622 | AT12: =IF($A12<>"Yes","",IF($R12="Detailed Breakdown","Detailed input",IF($R12="Contractor Quote","Estimated allocation - request vendor split","Planning allocation"))) -> Detailed input | AU12: Typical | AV12: =IF($A12<>"Yes",0,IF($AU12="Low",$L12*$N12,IF($AU12="High",$L12*$P12,$L12*$O12))) -> 11246 | AW12: =IF($A12<>"Yes",0,$AV12*(1+$T12)) -> 12370.6 | AX12: =IF(AND($A12="Yes",$AL12>0),$AL12*(1+$T12),0) -> 13970 | AY12: =IF($AX12>0,$AW12,0) -> 12370.6 | AZ12: =IF($AX12>0,$AX12-$AY12,0) -> 1599.4 | BA12: =IF($AY12=0,0,$AZ12/$AY12) -> 0.12929041 | BB12: =IF($A12<>"Yes","",IF($Q12>0,"Quoted",IF($AL12>0,"Detailed","Ballpark"))) -> Detailed
A13: Yes | B13: APP-005 | C13: =IFERROR(VLOOKUP($B13,'Cost Library'!$A$2:$M$159,2,FALSE),"") -> Appliances & Curb Appeal | D13: =IFERROR(VLOOKUP($B13,'Cost Library'!$A$2:$M$159,3,FALSE),"") -> Painting | E13: Front entry | F13: Refinish/paint front door for curb appeal | G13: =IFERROR(VLOOKUP($B13,'Cost Library'!$A$2:$M$159,5,FALSE),"") -> Renovation | H13: Interior Designer | I13: Low | J13: No | K13: P3 - Value Add | L13: 1 | M13: =IFERROR(VLOOKUP($B13,'Cost Library'!$A$2:$M$159,6,FALSE),"") -> each | N13: =IFERROR(VLOOKUP($B13,'Cost Library'!$A$2:$M$159,7,FALSE),0) -> 200 | O13: =IFERROR(VLOOKUP($B13,'Cost Library'!$A$2:$M$159,8,FALSE),0) -> 400 | P13: =IFERROR(VLOOKUP($B13,'Cost Library'!$A$2:$M$159,9,FALSE),0) -> 700 | R13: Detailed Breakdown | S13: =IF($A13<>"Yes",0,IF($R13="Detailed Breakdown",$AL13,IF($R13="Contractor Quote",$Q13,IF($R13="Low",$L13*$N13,IF($R13="High",$L13*$P13,$L13*$O13))))) -> 450 | T13: ='Project Inputs'!$C$15 -> 0.1 | U13: =IF($A13<>"Yes",0,$S13*(1+$T13)) -> 495 | V13: Approved | W13: =IFERROR(VLOOKUP($B13,'Cost Library'!$A$2:$M$159,10,FALSE),"") -> No | X13: 1 | Y13: 1500 | Z13: 3 | AA13: Example Handyman | AB13: Late-stage curb appeal | AC13: Small value-add item | AD13: 1 | AE13: 150 | AF13: =IF(OR(AD13="",AE13=""),0,AD13*AE13) -> 150 | AG13: 1 | AH13: 250 | AI13: =IF(OR(AG13="",AH13=""),0,AG13*AH13) -> 250 | AJ13: 0 | AK13: 50 | AL13: =SUM(AF13,AI13,AJ13,AK13) -> 450 | AM13: =IF($A13<>"Yes",0,IF($R13="Detailed Breakdown",$AF13,$S13*IFERROR(VLOOKUP($B13,'Cost Library'!$A$2:$Q$159,14,FALSE),0.4))) -> 150 | AN13: =IF($A13<>"Yes",0,IF($R13="Detailed Breakdown",$AI13,$S13*IFERROR(VLOOKUP($B13,'Cost Library'!$A$2:$Q$159,15,FALSE),0.5))) -> 250 | AO13: =IF($A13<>"Yes",0,IF($R13="Detailed Breakdown",$AJ13+$AK13,$S13*IFERROR(VLOOKUP($B13,'Cost Library'!$A$2:$Q$159,16,FALSE),0.1))) -> 50 | AP13: =IF($A13<>"Yes",0,$U13-$S13) -> 45 | AQ13: =IF($S13=0,0,$AM13/$S13) -> 0.33333333 | AR13: =IF($S13=0,0,$AN13/$S13) -> 0.55555556 | AS13: =IF($S13=0,0,$AO13/$S13) -> 0.11111111 | AT13: =IF($A13<>"Yes","",IF($R13="Detailed Breakdown","Detailed input",IF($R13="Contractor Quote","Estimated allocation - request vendor split","Planning allocation"))) -> Detailed input | AU13: Typical | AV13: =IF($A13<>"Yes",0,IF($AU13="Low",$L13*$N13,IF($AU13="High",$L13*$P13,$L13*$O13))) -> 400 | AW13: =IF($A13<>"Yes",0,$AV13*(1+$T13)) -> 440 | AX13: =IF(AND($A13="Yes",$AL13>0),$AL13*(1+$T13),0) -> 495 | AY13: =IF($AX13>0,$AW13,0) -> 440 | AZ13: =IF($AX13>0,$AX13-$AY13,0) -> 55 | BA13: =IF($AY13=0,0,$AZ13/$AY13) -> 0.125 | BB13: =IF($A13<>"Yes","",IF($Q13>0,"Quoted",IF($AL13>0,"Detailed","Ballpark"))) -> Detailed
A14: Yes | B14: WND-002 | C14: =IFERROR(VLOOKUP($B14,'Cost Library'!$A$2:$M$159,2,FALSE),"") -> Windows, Doors & Garage | D14: =IFERROR(VLOOKUP($B14,'Cost Library'!$A$2:$M$159,3,FALSE),"") -> Window | E14: Bedrooms / living room | F14: Replace six failed/dated standard windows | G14: =IFERROR(VLOOKUP($B14,'Cost Library'!$A$2:$M$159,5,FALSE),"") -> Replace | H14: Home Inspector | I14: Medium | J14: No | K14: P2 - Before Sale | L14: 6 | M14: =IFERROR(VLOOKUP($B14,'Cost Library'!$A$2:$M$159,6,FALSE),"") -> each | N14: =IFERROR(VLOOKUP($B14,'Cost Library'!$A$2:$M$159,7,FALSE),0) -> 400 | O14: =IFERROR(VLOOKUP($B14,'Cost Library'!$A$2:$M$159,8,FALSE),0) -> 750 | P14: =IFERROR(VLOOKUP($B14,'Cost Library'!$A$2:$M$159,9,FALSE),0) -> 1200 | R14: Detailed Breakdown | S14: =IF($A14<>"Yes",0,IF($R14="Detailed Breakdown",$AL14,IF($R14="Contractor Quote",$Q14,IF($R14="Low",$L14*$N14,IF($R14="High",$L14*$P14,$L14*$O14))))) -> 5400 | T14: ='Project Inputs'!$C$15 -> 0.1 | U14: =IF($A14<>"Yes",0,$S14*(1+$T14)) -> 5940 | V14: Quoted | W14: =IFERROR(VLOOKUP($B14,'Cost Library'!$A$2:$M$159,10,FALSE),"") -> Sometimes | X14: 3 | Y14: 6000 | Z14: 3 | AA14: Example Window Installer | AB14: Before interior trim touch-up | AC14: Six-window example | AD14: 6 | AE14: 550 | AF14: =IF(OR(AD14="",AE14=""),0,AD14*AE14) -> 3300 | AG14: 6 | AH14: 300 | AI14: =IF(OR(AG14="",AH14=""),0,AG14*AH14) -> 1800 | AJ14: 200 | AK14: 100 | AL14: =SUM(AF14,AI14,AJ14,AK14) -> 5400 | AM14: =IF($A14<>"Yes",0,IF($R14="Detailed Breakdown",$AF14,$S14*IFERROR(VLOOKUP($B14,'Cost Library'!$A$2:$Q$159,14,FALSE),0.4))) -> 3300 | AN14: =IF($A14<>"Yes",0,IF($R14="Detailed Breakdown",$AI14,$S14*IFERROR(VLOOKUP($B14,'Cost Library'!$A$2:$Q$159,15,FALSE),0.5))) -> 1800 | AO14: =IF($A14<>"Yes",0,IF($R14="Detailed Breakdown",$AJ14+$AK14,$S14*IFERROR(VLOOKUP($B14,'Cost Library'!$A$2:$Q$159,16,FALSE),0.1))) -> 300 | AP14: =IF($A14<>"Yes",0,$U14-$S14) -> 540 | AQ14: =IF($S14=0,0,$AM14/$S14) -> 0.61111111 | AR14: =IF($S14=0,0,$AN14/$S14) -> 0.33333333 | AS14: =IF($S14=0,0,$AO14/$S14) -> 0.055555556 | AT14: =IF($A14<>"Yes","",IF($R14="Detailed Breakdown","Detailed input",IF($R14="Contractor Quote","Estimated allocation - request vendor split","Planning allocation"))) -> Detailed input | AU14: Typical | AV14: =IF($A14<>"Yes",0,IF($AU14="Low",$L14*$N14,IF($AU14="High",$L14*$P14,$L14*$O14))) -> 4500 | AW14: =IF($A14<>"Yes",0,$AV14*(1+$T14)) -> 4950 | AX14: =IF(AND($A14="Yes",$AL14>0),$AL14*(1+$T14),0) -> 5940 | AY14: =IF($AX14>0,$AW14,0) -> 4950 | AZ14: =IF($AX14>0,$AX14-$AY14,0) -> 990 | BA14: =IF($AY14=0,0,$AZ14/$AY14) -> 0.2 | BB14: =IF($A14<>"Yes","",IF($Q14>0,"Quoted",IF($AL14>0,"Detailed","Ballpark"))) -> Detailed
A15: Yes | B15: EXT-013 | C15: =IFERROR(VLOOKUP($B15,'Cost Library'!$A$2:$M$159,2,FALSE),"") -> Exterior & Site | D15: =IFERROR(VLOOKUP($B15,'Cost Library'!$A$2:$M$159,3,FALSE),"") -> Landscaping | E15: Front / rear yard | F15: Basic landscaping and curb-appeal refresh | G15: =IFERROR(VLOOKUP($B15,'Cost Library'!$A$2:$M$159,5,FALSE),"") -> Renovation | H15: Interior Designer | I15: Low | J15: No | K15: P3 - Value Add | L15: 1 | M15: =IFERROR(VLOOKUP($B15,'Cost Library'!$A$2:$M$159,6,FALSE),"") -> project | N15: =IFERROR(VLOOKUP($B15,'Cost Library'!$A$2:$M$159,7,FALSE),0) -> 500 | O15: =IFERROR(VLOOKUP($B15,'Cost Library'!$A$2:$M$159,8,FALSE),0) -> 2000 | P15: =IFERROR(VLOOKUP($B15,'Cost Library'!$A$2:$M$159,9,FALSE),0) -> 6000 | R15: Detailed Breakdown | S15: =IF($A15<>"Yes",0,IF($R15="Detailed Breakdown",$AL15,IF($R15="Contractor Quote",$Q15,IF($R15="Low",$L15*$N15,IF($R15="High",$L15*$P15,$L15*$O15))))) -> 2300 | T15: ='Project Inputs'!$C$15 -> 0.1 | U15: =IF($A15<>"Yes",0,$S15*(1+$T15)) -> 2530 | V15: Approved | W15: =IFERROR(VLOOKUP($B15,'Cost Library'!$A$2:$M$159,10,FALSE),"") -> No | X15: 2 | Y15: 3000 | Z15: 4 | AA15: Example Landscape Crew | AB15: Final exterior phase | AC15: Mulch, pruning, lawn repair and cleanup | AD15: 1 | AE15: 1000 | AF15: =IF(OR(AD15="",AE15=""),0,AD15*AE15) -> 1000 | AG15: 1 | AH15: 1000 | AI15: =IF(OR(AG15="",AH15=""),0,AG15*AH15) -> 1000 | AJ15: 300 | AK15: 0 | AL15: =SUM(AF15,AI15,AJ15,AK15) -> 2300 | AM15: =IF($A15<>"Yes",0,IF($R15="Detailed Breakdown",$AF15,$S15*IFERROR(VLOOKUP($B15,'Cost Library'!$A$2:$Q$159,14,FALSE),0.4))) -> 1000 | AN15: =IF($A15<>"Yes",0,IF($R15="Detailed Breakdown",$AI15,$S15*IFERROR(VLOOKUP($B15,'Cost Library'!$A$2:$Q$159,15,FALSE),0.5))) -> 1000 | AO15: =IF($A15<>"Yes",0,IF($R15="Detailed Breakdown",$AJ15+$AK15,$S15*IFERROR(VLOOKUP($B15,'Cost Library'!$A$2:$Q$159,16,FALSE),0.1))) -> 300 | AP15: =IF($A15<>"Yes",0,$U15-$S15) -> 230 | AQ15: =IF($S15=0,0,$AM15/$S15) -> 0.43478261 | AR15: =IF($S15=0,0,$AN15/$S15) -> 0.43478261 | AS15: =IF($S15=0,0,$AO15/$S15) -> 0.13043478 | AT15: =IF($A15<>"Yes","",IF($R15="Detailed Breakdown","Detailed input",IF($R15="Contractor Quote","Estimated allocation - request vendor split","Planning allocation"))) -> Detailed input | AU15: Typical | AV15: =IF($A15<>"Yes",0,IF($AU15="Low",$L15*$N15,IF($AU15="High",$L15*$P15,$L15*$O15))) -> 2000 | AW15: =IF($A15<>"Yes",0,$AV15*(1+$T15)) -> 2200 | AX15: =IF(AND($A15="Yes",$AL15>0),$AL15*(1+$T15),0) -> 2530 | AY15: =IF($AX15>0,$AW15,0) -> 2200 | AZ15: =IF($AX15>0,$AX15-$AY15,0) -> 330 | BA15: =IF($AY15=0,0,$AZ15/$AY15) -> 0.15 | BB15: =IF($A15<>"Yes","",IF($Q15>0,"Quoted",IF($AL15>0,"Detailed","Ballpark"))) -> Detailed
A16: No | C16: =IFERROR(VLOOKUP($B16,'Cost Library'!$A$2:$M$159,2,FALSE),"") | D16: =IFERROR(VLOOKUP($B16,'Cost Library'!$A$2:$M$159,3,FALSE),"") | G16: =IFERROR(VLOOKUP($B16,'Cost Library'!$A$2:$M$159,5,FALSE),"") | L16: 1 | M16: =IFERROR(VLOOKUP($B16,'Cost Library'!$A$2:$M$159,6,FALSE),"") | N16: =IFERROR(VLOOKUP($B16,'Cost Library'!$A$2:$M$159,7,FALSE),0) -> 0 | O16: =IFERROR(VLOOKUP($B16,'Cost Library'!$A$2:$M$159,8,FALSE),0) -> 0 | P16: =IFERROR(VLOOKUP($B16,'Cost Library'!$A$2:$M$159,9,FALSE),0) -> 0 | R16: Typical | S16: =IF($A16<>"Yes",0,IF($R16="Detailed Breakdown",$AL16,IF($R16="Contractor Quote",$Q16,IF($R16="Low",$L16*$N16,IF($R16="High",$L16*$P16,$L16*$O16))))) -> 0 | T16: ='Project Inputs'!$C$15 -> 0.1 | U16: =IF($A16<>"Yes",0,$S16*(1+$T16)) -> 0 | V16: Not Started | W16: =IFERROR(VLOOKUP($B16,'Cost Library'!$A$2:$M$159,10,FALSE),"") | AF16: =IF(OR(AD16="",AE16=""),0,AD16*AE16) -> 0 | AI16: =IF(OR(AG16="",AH16=""),0,AG16*AH16) -> 0 | AL16: =SUM(AF16,AI16,AJ16,AK16) -> 0 | AM16: =IF($A16<>"Yes",0,IF($R16="Detailed Breakdown",$AF16,$S16*IFERROR(VLOOKUP($B16,'Cost Library'!$A$2:$Q$159,14,FALSE),0.4))) -> 0 | AN16: =IF($A16<>"Yes",0,IF($R16="Detailed Breakdown",$AI16,$S16*IFERROR(VLOOKUP($B16,'Cost Library'!$A$2:$Q$159,15,FALSE),0.5))) -> 0 | AO16: =IF($A16<>"Yes",0,IF($R16="Detailed Breakdown",$AJ16+$AK16,$S16*IFERROR(VLOOKUP($B16,'Cost Library'!$A$2:$Q$159,16,FALSE),0.1))) -> 0 | AP16: =IF($A16<>"Yes",0,$U16-$S16) -> 0 | AQ16: =IF($S16=0,0,$AM16/$S16) -> 0 | AR16: =IF($S16=0,0,$AN16/$S16) -> 0 | AS16: =IF($S16=0,0,$AO16/$S16) -> 0 | AT16: =IF($A16<>"Yes","",IF($R16="Detailed Breakdown","Detailed input",IF($R16="Contractor Quote","Estimated allocation - request vendor split","Planning allocation"))) | AU16: Typical | AV16: =IF($A16<>"Yes",0,IF($AU16="Low",$L16*$N16,IF($AU16="High",$L16*$P16,$L16*$O16))) -> 0 | AW16: =IF($A16<>"Yes",0,$AV16*(1+$T16)) -> 0 | AX16: =IF(AND($A16="Yes",$AL16>0),$AL16*(1+$T16),0) -> 0 | AY16: =IF($AX16>0,$AW16,0) -> 0 | AZ16: =IF($AX16>0,$AX16-$AY16,0) -> 0 | BA16: =IF($AY16=0,0,$AZ16/$AY16) -> 0 | BB16: =IF($A16<>"Yes","",IF($Q16>0,"Quoted",IF($AL16>0,"Detailed","Ballpark")))
A17: No | C17: =IFERROR(VLOOKUP($B17,'Cost Library'!$A$2:$M$159,2,FALSE),"") | D17: =IFERROR(VLOOKUP($B17,'Cost Library'!$A$2:$M$159,3,FALSE),"") | G17: =IFERROR(VLOOKUP($B17,'Cost Library'!$A$2:$M$159,5,FALSE),"") | L17: 1 | M17: =IFERROR(VLOOKUP($B17,'Cost Library'!$A$2:$M$159,6,FALSE),"") | N17: =IFERROR(VLOOKUP($B17,'Cost Library'!$A$2:$M$159,7,FALSE),0) -> 0 | O17: =IFERROR(VLOOKUP($B17,'Cost Library'!$A$2:$M$159,8,FALSE),0) -> 0 | P17: =IFERROR(VLOOKUP($B17,'Cost Library'!$A$2:$M$159,9,FALSE),0) -> 0 | R17: Typical | S17: =IF($A17<>"Yes",0,IF($R17="Detailed Breakdown",$AL17,IF($R17="Contractor Quote",$Q17,IF($R17="Low",$L17*$N17,IF($R17="High",$L17*$P17,$L17*$O17))))) -> 0 | T17: ='Project Inputs'!$C$15 -> 0.1 | U17: =IF($A17<>"Yes",0,$S17*(1+$T17)) -> 0 | V17: Not Started | W17: =IFERROR(VLOOKUP($B17,'Cost Library'!$A$2:$M$159,10,FALSE),"") | AF17: =IF(OR(AD17="",AE17=""),0,AD17*AE17) -> 0 | AI17: =IF(OR(AG17="",AH17=""),0,AG17*AH17) -> 0 | AL17: =SUM(AF17,AI17,AJ17,AK17) -> 0 | AM17: =IF($A17<>"Yes",0,IF($R17="Detailed Breakdown",$AF17,$S17*IFERROR(VLOOKUP($B17,'Cost Library'!$A$2:$Q$159,14,FALSE),0.4))) -> 0 | AN17: =IF($A17<>"Yes",0,IF($R17="Detailed Breakdown",$AI17,$S17*IFERROR(VLOOKUP($B17,'Cost Library'!$A$2:$Q$159,15,FALSE),0.5))) -> 0 | AO17: =IF($A17<>"Yes",0,IF($R17="Detailed Breakdown",$AJ17+$AK17,$S17*IFERROR(VLOOKUP($B17,'Cost Library'!$A$2:$Q$159,16,FALSE),0.1))) -> 0 | AP17: =IF($A17<>"Yes",0,$U17-$S17) -> 0 | AQ17: =IF($S17=0,0,$AM17/$S17) -> 0 | AR17: =IF($S17=0,0,$AN17/$S17) -> 0 | AS17: =IF($S17=0,0,$AO17/$S17) -> 0 | AT17: =IF($A17<>"Yes","",IF($R17="Detailed Breakdown","Detailed input",IF($R17="Contractor Quote","Estimated allocation - request vendor split","Planning allocation"))) | AU17: Typical | AV17: =IF($A17<>"Yes",0,IF($AU17="Low",$L17*$N17,IF($AU17="High",$L17*$P17,$L17*$O17))) -> 0 | AW17: =IF($A17<>"Yes",0,$AV17*(1+$T17)) -> 0 | AX17: =IF(AND($A17="Yes",$AL17>0),$AL17*(1+$T17),0) -> 0 | AY17: =IF($AX17>0,$AW17,0) -> 0 | AZ17: =IF($AX17>0,$AX17-$AY17,0) -> 0 | BA17: =IF($AY17=0,0,$AZ17/$AY17) -> 0 | BB17: =IF($A17<>"Yes","",IF($Q17>0,"Quoted",IF($AL17>0,"Detailed","Ballpark")))
A18: No | C18: =IFERROR(VLOOKUP($B18,'Cost Library'!$A$2:$M$159,2,FALSE),"") | D18: =IFERROR(VLOOKUP($B18,'Cost Library'!$A$2:$M$159,3,FALSE),"") | G18: =IFERROR(VLOOKUP($B18,'Cost Library'!$A$2:$M$159,5,FALSE),"") | L18: 1 | M18: =IFERROR(VLOOKUP($B18,'Cost Library'!$A$2:$M$159,6,FALSE),"") | N18: =IFERROR(VLOOKUP($B18,'Cost Library'!$A$2:$M$159,7,FALSE),0) -> 0 | O18: =IFERROR(VLOOKUP($B18,'Cost Library'!$A$2:$M$159,8,FALSE),0) -> 0 | P18: =IFERROR(VLOOKUP($B18,'Cost Library'!$A$2:$M$159,9,FALSE),0) -> 0 | R18: Typical | S18: =IF($A18<>"Yes",0,IF($R18="Detailed Breakdown",$AL18,IF($R18="Contractor Quote",$Q18,IF($R18="Low",$L18*$N18,IF($R18="High",$L18*$P18,$L18*$O18))))) -> 0 | T18: ='Project Inputs'!$C$15 -> 0.1 | U18: =IF($A18<>"Yes",0,$S18*(1+$T18)) -> 0 | V18: Not Started | W18: =IFERROR(VLOOKUP($B18,'Cost Library'!$A$2:$M$159,10,FALSE),"") | AF18: =IF(OR(AD18="",AE18=""),0,AD18*AE18) -> 0 | AI18: =IF(OR(AG18="",AH18=""),0,AG18*AH18) -> 0 | AL18: =SUM(AF18,AI18,AJ18,AK18) -> 0 | AM18: =IF($A18<>"Yes",0,IF($R18="Detailed Breakdown",$AF18,$S18*IFERROR(VLOOKUP($B18,'Cost Library'!$A$2:$Q$159,14,FALSE),0.4))) -> 0 | AN18: =IF($A18<>"Yes",0,IF($R18="Detailed Breakdown",$AI18,$S18*IFERROR(VLOOKUP($B18,'Cost Library'!$A$2:$Q$159,15,FALSE),0.5))) -> 0 | AO18: =IF($A18<>"Yes",0,IF($R18="Detailed Breakdown",$AJ18+$AK18,$S18*IFERROR(VLOOKUP($B18,'Cost Library'!$A$2:$Q$159,16,FALSE),0.1))) -> 0 | AP18: =IF($A18<>"Yes",0,$U18-$S18) -> 0 | AQ18: =IF($S18=0,0,$AM18/$S18) -> 0 | AR18: =IF($S18=0,0,$AN18/$S18) -> 0 | AS18: =IF($S18=0,0,$AO18/$S18) -> 0 | AT18: =IF($A18<>"Yes","",IF($R18="Detailed Breakdown","Detailed input",IF($R18="Contractor Quote","Estimated allocation - request vendor split","Planning allocation"))) | AU18: Typical | AV18: =IF($A18<>"Yes",0,IF($AU18="Low",$L18*$N18,IF($AU18="High",$L18*$P18,$L18*$O18))) -> 0 | AW18: =IF($A18<>"Yes",0,$AV18*(1+$T18)) -> 0 | AX18: =IF(AND($A18="Yes",$AL18>0),$AL18*(1+$T18),0) -> 0 | AY18: =IF($AX18>0,$AW18,0) -> 0 | AZ18: =IF($AX18>0,$AX18-$AY18,0) -> 0 | BA18: =IF($AY18=0,0,$AZ18/$AY18) -> 0 | BB18: =IF($A18<>"Yes","",IF($Q18>0,"Quoted",IF($AL18>0,"Detailed","Ballpark")))
A19: No | C19: =IFERROR(VLOOKUP($B19,'Cost Library'!$A$2:$M$159,2,FALSE),"") | D19: =IFERROR(VLOOKUP($B19,'Cost Library'!$A$2:$M$159,3,FALSE),"") | G19: =IFERROR(VLOOKUP($B19,'Cost Library'!$A$2:$M$159,5,FALSE),"") | L19: 1 | M19: =IFERROR(VLOOKUP($B19,'Cost Library'!$A$2:$M$159,6,FALSE),"") | N19: =IFERROR(VLOOKUP($B19,'Cost Library'!$A$2:$M$159,7,FALSE),0) -> 0 | O19: =IFERROR(VLOOKUP($B19,'Cost Library'!$A$2:$M$159,8,FALSE),0) -> 0 | P19: =IFERROR(VLOOKUP($B19,'Cost Library'!$A$2:$M$159,9,FALSE),0) -> 0 | R19: Typical | S19: =IF($A19<>"Yes",0,IF($R19="Detailed Breakdown",$AL19,IF($R19="Contractor Quote",$Q19,IF($R19="Low",$L19*$N19,IF($R19="High",$L19*$P19,$L19*$O19))))) -> 0 | T19: ='Project Inputs'!$C$15 -> 0.1 | U19: =IF($A19<>"Yes",0,$S19*(1+$T19)) -> 0 | V19: Not Started | W19: =IFERROR(VLOOKUP($B19,'Cost Library'!$A$2:$M$159,10,FALSE),"") | AF19: =IF(OR(AD19="",AE19=""),0,AD19*AE19) -> 0 | AI19: =IF(OR(AG19="",AH19=""),0,AG19*AH19) -> 0 | AL19: =SUM(AF19,AI19,AJ19,AK19) -> 0 | AM19: =IF($A19<>"Yes",0,IF($R19="Detailed Breakdown",$AF19,$S19*IFERROR(VLOOKUP($B19,'Cost Library'!$A$2:$Q$159,14,FALSE),0.4))) -> 0 | AN19: =IF($A19<>"Yes",0,IF($R19="Detailed Breakdown",$AI19,$S19*IFERROR(VLOOKUP($B19,'Cost Library'!$A$2:$Q$159,15,FALSE),0.5))) -> 0 | AO19: =IF($A19<>"Yes",0,IF($R19="Detailed Breakdown",$AJ19+$AK19,$S19*IFERROR(VLOOKUP($B19,'Cost Library'!$A$2:$Q$159,16,FALSE),0.1))) -> 0 | AP19: =IF($A19<>"Yes",0,$U19-$S19) -> 0 | AQ19: =IF($S19=0,0,$AM19/$S19) -> 0 | AR19: =IF($S19=0,0,$AN19/$S19) -> 0 | AS19: =IF($S19=0,0,$AO19/$S19) -> 0 | AT19: =IF($A19<>"Yes","",IF($R19="Detailed Breakdown","Detailed input",IF($R19="Contractor Quote","Estimated allocation - request vendor split","Planning allocation"))) | AU19: Typical | AV19: =IF($A19<>"Yes",0,IF($AU19="Low",$L19*$N19,IF($AU19="High",$L19*$P19,$L19*$O19))) -> 0 | AW19: =IF($A19<>"Yes",0,$AV19*(1+$T19)) -> 0 | AX19: =IF(AND($A19="Yes",$AL19>0),$AL19*(1+$T19),0) -> 0 | AY19: =IF($AX19>0,$AW19,0) -> 0 | AZ19: =IF($AX19>0,$AX19-$AY19,0) -> 0 | BA19: =IF($AY19=0,0,$AZ19/$AY19) -> 0 | BB19: =IF($A19<>"Yes","",IF($Q19>0,"Quoted",IF($AL19>0,"Detailed","Ballpark")))
A20: No | C20: =IFERROR(VLOOKUP($B20,'Cost Library'!$A$2:$M$159,2,FALSE),"") | D20: =IFERROR(VLOOKUP($B20,'Cost Library'!$A$2:$M$159,3,FALSE),"") | G20: =IFERROR(VLOOKUP($B20,'Cost Library'!$A$2:$M$159,5,FALSE),"") | L20: 1 | M20: =IFERROR(VLOOKUP($B20,'Cost Library'!$A$2:$M$159,6,FALSE),"") | N20: =IFERROR(VLOOKUP($B20,'Cost Library'!$A$2:$M$159,7,FALSE),0) -> 0 | O20: =IFERROR(VLOOKUP($B20,'Cost Library'!$A$2:$M$159,8,FALSE),0) -> 0 | P20: =IFERROR(VLOOKUP($B20,'Cost Library'!$A$2:$M$159,9,FALSE),0) -> 0 | R20: Typical | S20: =IF($A20<>"Yes",0,IF($R20="Detailed Breakdown",$AL20,IF($R20="Contractor Quote",$Q20,IF($R20="Low",$L20*$N20,IF($R20="High",$L20*$P20,$L20*$O20))))) -> 0 | T20: ='Project Inputs'!$C$15 -> 0.1 | U20: =IF($A20<>"Yes",0,$S20*(1+$T20)) -> 0 | V20: Not Started | W20: =IFERROR(VLOOKUP($B20,'Cost Library'!$A$2:$M$159,10,FALSE),"") | AF20: =IF(OR(AD20="",AE20=""),0,AD20*AE20) -> 0 | AI20: =IF(OR(AG20="",AH20=""),0,AG20*AH20) -> 0 | AL20: =SUM(AF20,AI20,AJ20,AK20) -> 0 | AM20: =IF($A20<>"Yes",0,IF($R20="Detailed Breakdown",$AF20,$S20*IFERROR(VLOOKUP($B20,'Cost Library'!$A$2:$Q$159,14,FALSE),0.4))) -> 0 | AN20: =IF($A20<>"Yes",0,IF($R20="Detailed Breakdown",$AI20,$S20*IFERROR(VLOOKUP($B20,'Cost Library'!$A$2:$Q$159,15,FALSE),0.5))) -> 0 | AO20: =IF($A20<>"Yes",0,IF($R20="Detailed Breakdown",$AJ20+$AK20,$S20*IFERROR(VLOOKUP($B20,'Cost Library'!$A$2:$Q$159,16,FALSE),0.1))) -> 0 | AP20: =IF($A20<>"Yes",0,$U20-$S20) -> 0 | AQ20: =IF($S20=0,0,$AM20/$S20) -> 0 | AR20: =IF($S20=0,0,$AN20/$S20) -> 0 | AS20: =IF($S20=0,0,$AO20/$S20) -> 0 | AT20: =IF($A20<>"Yes","",IF($R20="Detailed Breakdown","Detailed input",IF($R20="Contractor Quote","Estimated allocation - request vendor split","Planning allocation"))) | AU20: Typical | AV20: =IF($A20<>"Yes",0,IF($AU20="Low",$L20*$N20,IF($AU20="High",$L20*$P20,$L20*$O20))) -> 0 | AW20: =IF($A20<>"Yes",0,$AV20*(1+$T20)) -> 0 | AX20: =IF(AND($A20="Yes",$AL20>0),$AL20*(1+$T20),0) -> 0 | AY20: =IF($AX20>0,$AW20,0) -> 0 | AZ20: =IF($AX20>0,$AX20-$AY20,0) -> 0 | BA20: =IF($AY20=0,0,$AZ20/$AY20) -> 0 | BB20: =IF($A20<>"Yes","",IF($Q20>0,"Quoted",IF($AL20>0,"Detailed","Ballpark")))
A21: No | C21: =IFERROR(VLOOKUP($B21,'Cost Library'!$A$2:$M$159,2,FALSE),"") | D21: =IFERROR(VLOOKUP($B21,'Cost Library'!$A$2:$M$159,3,FALSE),"") | G21: =IFERROR(VLOOKUP($B21,'Cost Library'!$A$2:$M$159,5,FALSE),"") | L21: 1 | M21: =IFERROR(VLOOKUP($B21,'Cost Library'!$A$2:$M$159,6,FALSE),"") | N21: =IFERROR(VLOOKUP($B21,'Cost Library'!$A$2:$M$159,7,FALSE),0) -> 0 | O21: =IFERROR(VLOOKUP($B21,'Cost Library'!$A$2:$M$159,8,FALSE),0) -> 0 | P21: =IFERROR(VLOOKUP($B21,'Cost Library'!$A$2:$M$159,9,FALSE),0) -> 0 | R21: Typical | S21: =IF($A21<>"Yes",0,IF($R21="Detailed Breakdown",$AL21,IF($R21="Contractor Quote",$Q21,IF($R21="Low",$L21*$N21,IF($R21="High",$L21*$P21,$L21*$O21))))) -> 0 | T21: ='Project Inputs'!$C$15 -> 0.1 | U21: =IF($A21<>"Yes",0,$S21*(1+$T21)) -> 0 | V21: Not Started | W21: =IFERROR(VLOOKUP($B21,'Cost Library'!$A$2:$M$159,10,FALSE),"") | AF21: =IF(OR(AD21="",AE21=""),0,AD21*AE21) -> 0 | AI21: =IF(OR(AG21="",AH21=""),0,AG21*AH21) -> 0 | AL21: =SUM(AF21,AI21,AJ21,AK21) -> 0 | AM21: =IF($A21<>"Yes",0,IF($R21="Detailed Breakdown",$AF21,$S21*IFERROR(VLOOKUP($B21,'Cost Library'!$A$2:$Q$159,14,FALSE),0.4))) -> 0 | AN21: =IF($A21<>"Yes",0,IF($R21="Detailed Breakdown",$AI21,$S21*IFERROR(VLOOKUP($B21,'Cost Library'!$A$2:$Q$159,15,FALSE),0.5))) -> 0 | AO21: =IF($A21<>"Yes",0,IF($R21="Detailed Breakdown",$AJ21+$AK21,$S21*IFERROR(VLOOKUP($B21,'Cost Library'!$A$2:$Q$159,16,FALSE),0.1))) -> 0 | AP21: =IF($A21<>"Yes",0,$U21-$S21) -> 0 | AQ21: =IF($S21=0,0,$AM21/$S21) -> 0 | AR21: =IF($S21=0,0,$AN21/$S21) -> 0 | AS21: =IF($S21=0,0,$AO21/$S21) -> 0 | AT21: =IF($A21<>"Yes","",IF($R21="Detailed Breakdown","Detailed input",IF($R21="Contractor Quote","Estimated allocation - request vendor split","Planning allocation"))) | AU21: Typical | AV21: =IF($A21<>"Yes",0,IF($AU21="Low",$L21*$N21,IF($AU21="High",$L21*$P21,$L21*$O21))) -> 0 | AW21: =IF($A21<>"Yes",0,$AV21*(1+$T21)) -> 0 | AX21: =IF(AND($A21="Yes",$AL21>0),$AL21*(1+$T21),0) -> 0 | AY21: =IF($AX21>0,$AW21,0) -> 0 | AZ21: =IF($AX21>0,$AX21-$AY21,0) -> 0 | BA21: =IF($AY21=0,0,$AZ21/$AY21) -> 0 | BB21: =IF($A21<>"Yes","",IF($Q21>0,"Quoted",IF($AL21>0,"Detailed","Ballpark")))
